Workbook
Name data2: Data_2!$C$3:$I$17
Name student: Data_2!$C$4:$C$17

Sheet Index
A1: S.N. | B1: DAYS | C1: TOPIC | D1: UPPER | F1: PENDING EXCEL TOPICS
A2: 1 | B2: DAY-1 | C2: MATCH FUNCTION | F2: MEAN, MEDIAN
A3: 2 | B3: DAY-2 | C3: INDEX
A4: 3 | B4: DAY-3 | C4: INDEX AND MATCH LOOKUP A VALUE ON THE LEFT
A5: 4 | B5: DAY-4 | C5: INDEX AND MATCH 2 WAY LOOKUP
A6: 5 | B6: DAY-5 | C6: INDEX AND MATCH 2 WAY LOOKUP
A7: 6 | B7: DAY-6 | C7: INDEX AND MATCH 8 SUM A ROW BASED ON A CONDITION
A8: 7 | B8: DAY-7 | C8: INDEX AND MATCH 9 SUM A COLUMN BASED ON A CONDITION
A9: 8 | B9: DAY-8 | C9: INDEX AND MATCH WITH MIN FORMULA LOOKUP THE LOWEST VALUE
A10: 9 | B10: DAY-9 | C10: INDEX AND MATCH WITH MAX FORMULA LOOKUP THE HIGHEST VALUE
A11: 10 | B11: DAY-10 | C11: INDEX & MATCH FORMULA 12 REFERENCE & AREA TO LOOKUP ANS FROM 3 DIFFERENT TABLES
A12: 11 | B12: DAY-11 | C12: CONDITIONAL FORMATTING- FORMAT A CELL BASED ON A FORMULA
A13: 12 | B13: DAY-12 | C13: CONDITIONAL FORMATTING- HIGHLIGHT - COLOR A COLUMN BASED ON A FORMULA
A14: 13 | B14: DAY-13 | C14: VLOOKUP
... A26: 25 | B26: DAY-25 | C26: MEAN,MEDIAN, MODE, STANDARD DEVIATION AND STATISTICAL CHART
A27: 26 | B27: DAY-26 | C27: if | D27: =UPPER(Table1[[#This Row],[TOPIC]]) -> IF
A28: 27 | B28: DAY-27 | D28: =UPPER(Table1[[#This Row],[TOPIC]])
A29: 28 | B29: DAY-28 | D29: =UPPER(Table1[[#This Row],[TOPIC]])
A30: 29 | B30: DAY-29 | D30: =UPPER(Table1[[#This Row],[TOPIC]])
A31: 30 | B31: DAY-30 | D31: =UPPER(Table1[[#This Row],[TOPIC]])
A32: 31 | B32: DAY-31 | D32: =UPPER(Table1[[#This Row],[TOPIC]])
A33: 32 | B33: DAY-32 | D33: =UPPER(Table1[[#This Row],[TOPIC]])
A34: 33 | B34: DAY-33 | D34: =UPPER(Table1[[#This Row],[TOPIC]])
A35: 34 | B35: DAY-34 | D35: =UPPER(Table1[[#This Row],[TOPIC]])
A36: 35 | B36: DAY-35 | D36: =UPPER(Table1[[#This Row],[TOPIC]])
A37: 36 | B37: DAY-36 | D37: =UPPER(Table1[[#This Row],[TOPIC]])
A38: 37 | B38: DAY-37 | D38: =UPPER(Table1[[#This Row],[TOPIC]])
A39: 38 | B39: DAY-38 | D39: =UPPER(Table1[[#This Row],[TOPIC]])
... A51: 50 | B51: DAY-50 | D51: =UPPER(Table1[[#This Row],[TOPIC]])

Sheet Day-1
A1: Match Function with Exact Match
A2: MATCH(D4,$A$6:$A$10,0)
C4: Subject | D4: Math | E4: English | F4: Science | G4: History | H4: Geography
A5: Subject | D5: =MATCH(D4,$A$6:$A$10,0) -> 1 | E5: =MATCH(E4,$A$6:$A$10,0) -> 2 | F5: =MATCH(F4,$A$6:$A$10,0) -> 3 | G5: =MATCH(G4,$A$6:$A$10,0) -> 4 | H5: =MATCH(H4,$A$6:$A$10,0) -> 5
A6: Math
A7: English
A8: Science
A9: History
A10: Geography
A13: Match Function with Approximate and Excat Match
A14: MATCH(C17,$A$21:$A$28,1)
C16: Range | D16: Exact | E16: Greater than last | F16: Less than | G16: Greater than
B17: Match | C17: 125 | D17: 150 | E17: 20000 | F17: 50 | G17: 90
B18: Result | C18: =MATCH(C17,$A$21:$A$28,1) -> 1 | D18: =MATCH(D17,$A$21:$A$28,1) -> 2 | E18: =MATCH(E17,$A$21:$A$28,1) -> 8 | F18: =MATCH(F17,$A$21:$A$28,1) -> #N/A | G18: =MATCH(G17,$A$21:$A$28,1) -> #N/A
A20: List
A21: 100
A22: 150
A23: 250
A24: 500
A25: 1000
A26: 2000
A27: 3000
A28: 10000
A30: Match Function with Approximate and Excat Match
A31: MATCH(C33,$B$39:$H$39,1)
C33: Range | D33: Exact | E33: Greater than last | F33: Less than | G33: Greater than
B34: Match | C34: 125 | D34: 150 | E34: 20000 | F34: 50 | G34: 90
B35: Result | C35: =MATCH(C34,$B$38:$I$38,1) -> 1 | D35: =MATCH(D34,$B$38:$I$38,1) -> 2 | E35: =MATCH(E34,$B$38:$I$38,1) -> 8 | F35: =MATCH(F34,$B$38:$I$38,1) -> #N/A | G35: =MATCH(G34,$B$38:$I$38,1) -> #N/A
A38: List | B38: 100 | C38: 150 | D38: 250 | E38: 500 | F38: 1000 | G38: 2000 | H38: 3000 | I38: 10000
A41: Match Function with Excat Match
A42: MATCH(C45,B49:$I$49,0)
C44: Range | D44: Exact | E44: Greater than last | F44: Less than | G44: Greater than
B45: Match | C45: 125 | D45: 150 | E45: 20000 | F45: 50 | G45: 90
B46: Result | C46: =MATCH(C45,B49:$I$49,0) -> #N/A | D46: =MATCH(D45,C49:$I$49,0) -> 1 | E46: =MATCH(E45,D49:$I$49,0) -> #N/A | F46: =MATCH(F45,E49:$I$49,0) -> #N/A | G46: =MATCH(G45,F49:$I$49,0) -> #N/A
A49: List | B49: 100 | C49: 150 | D49: 250 | E49: 500 | F49: 1000 | G49: 2000 | H49: 3000 | I49: 10000
A52: Match Function with Approximate Reverse Match
A53: MATCH(C56,$A$60:$A$67,-1)
C55: Range | D55: Exact | E55: Greater than last | F55: Less than | G55: Greater than
B56: Match | C56: 125 | D56: 150 | E56: 20000 | F56: 50 | G56: 90
B57: Result | C57: =MATCH(C56,$A$60:$A$67,-1) -> 7 | D57: =MATCH(D56,$A$60:$A$67,-1) -> 7 | E57: =MATCH(E56,$A$60:$A$67,-1) -> #N/A | F57: =MATCH(F56,$A$60:$A$67,-1) -> 8 | G57: =MATCH(G56,$A$60:$A$67,-1) -> 8
...

Sheet Day-2
D2: INDEX(D7:I16,2,D19)
D4: SALESMAN
D5: 1 | E5: 2 | F5: 3 | G5: 4 | H5: 5 | I5: 6 | L5: 0.01
B6: UNITS | C6: 100 | D6: 0.07 | E6: 0.11 | F6: 0.14 | G6: 0.06 | H6: 0.14 | I6: 0.07
C7: 200 | D7: 0.07 | E7: 0.15 | F7: 0.17 | G7: 0.16 | H7: 0.07 | I7: 0.09
C8: 300 | D8: 0.17 | E8: 0.13 | F8: 0.07 | G8: 0.06 | H8: 0.16 | I8: 0.19
C9: 400 | D9: 0.11 | E9: 0.18 | F9: 0.09 | G9: 0.1 | H9: 0.15 | I9: 0.1
C10: 500 | D10: 0.1 | E10: 0.12 | F10: 0.15 | G10: 0.19 | H10: 0.16 | I10: 0.09
C11: 600 | D11: 0.16 | E11: 0.07 | F11: 0.1 | G11: 0.07 | H11: 0.19 | I11: 0.08
C12: 700 | D12: 0.16 | E12: 0.14 | F12: 0.18 | G12: 0.17 | H12: 0.15 | I12: 0.16
C13: 800 | D13: 0.07 | E13: 0.09 | F13: 0.13 | G13: 0.09 | H13: 0.15 | I13: 0.18
C14: 900 | D14: 0.17 | E14: 0.08 | F14: 0.13 | G14: 0.15 | H14: 0.06 | I14: 0.06
C15: 1000 | D15: 0.06 | E15: 0.19 | F15: 0.13 | G15: 0.1 | H15: 0.1 | I15: 0.17
C17: UNITS | D17: 200 | E17: Ans | F17: =INDEX(D6:I15,2,D18) -> 0.15
C18: SALESMAN | D18: 2

Sheet DAY-3
B2: Example - 1 | D2: INDEX(D5:D8,MATCH(C15,C5:C8,0))
B4: Brand | C4: Tablet
B5: Blackberry | C5: Playbook
B6: Apple | C6: Ipad
B7: Samsung | C7: Galaxy Tab
B8: Nokia | C8: There is none that I am aware of
B14: Brand name | C14: Tablet
B15: Samsung | C15: =INDEX(C5:C8,MATCH(B15,B5:B8,0)) -> Galaxy Tab
B18: Example - 2 | D18: INDEX(F20:I20,MATCH(C31,C21:C24,0))
B20: Brand | D20: Tablet | E20: Playbook | F20: Ipad | G20: Galaxy Tab | H20: There is none that I am aware of
B21: Blackberry
B22: Apple
B23: Samsung
B24: Nokia
B30: Brand name | C30: Tablet
B31: Samsung | C31: =INDEX(E20:H20,MATCH(B31,B21:B24,0)) -> Galaxy Tab
B34: Example - 3 | D34: INDEX(D39:D42,MATCH(C46,D36:G36,0))
B36: Brand | C36: Blackberry | D36: Apple | E36: Samsung | F36: Nokia
C38: Tablet
C39: Playbook
C40: Ipad
C41: Galaxy Tab
C42: There is none that I am aware of
B45: Brand name | C45: Tablet
B46: Samsung | C46: =INDEX(C39:C42,MATCH(B46,C36:F36,0)) -> Galaxy Tab
B49: Example - 4 | D49: INDEX(C52:C55,MATCH(C62,D52:D55,0))
B51: Brand | C51: Tablet
B52: Blackberry | C52: Playbook
B53: Apple | C53: Ipad
B54: Samsung | C54: Galaxy Tab
B55: Nokia | C55: There is none that I am aware of
B61: Tablet | C61: Brand name
B62: Galaxy Tab | C62: =INDEX(B52:B55,MATCH(B62,C52:C55,0)) -> Samsung

Sheet Day-4
E2: Exact Match
C3: INDEX(D7:I16,MATCH(D18,C7:C16,0),MATCH(D19,D6:I6,0))
D5: SALESMAN
D6: 1 | E6: 2 | F6: 3 | G6: 4 | H6: 5 | I6: 6 | L6: 0.01
B7: UNITS | C7: 100 | D7: 0.07 | E7: 0.11 | F7: 0.14 | G7: 0.06 | H7: 0.14 | I7: 0.07
C8: 200 | D8: 0.07 | E8: 0.15 | F8: 0.17 | G8: 0.16 | H8: 0.07 | I8: 0.09
C9: 300 | D9: 0.17 | E9: 0.13 | F9: 0.07 | G9: 0.06 | H9: 0.16 | I9: 0.19
C10: 400 | D10: 0.11 | E10: 0.18 | F10: 0.09 | G10: 0.1 | H10: 0.15 | I10: 0.1
C11: 500 | D11: 0.1 | E11: 0.12 | F11: 0.15 | G11: 0.19 | H11: 0.16 | I11: 0.09
C12: 600 | D12: 0.16 | E12: 0.07 | F12: 0.1 | G12: 0.07 | H12: 0.19 | I12: 0.08
C13: 700 | D13: 0.16 | E13: 0.14 | F13: 0.18 | G13: 0.17 | H13: 0.15 | I13: 0.16
C14: 800 | D14: 0.07 | E14: 0.09 | F14: 0.13 | G14: 0.09 | H14: 0.15 | I14: 0.18
C15: 900 | D15: 0.17 | E15: 0.08 | F15: 0.13 | G15: 0.15 | H15: 0.06 | I15: 0.06
C16: 1000 | D16: 0.06 | E16: 0.19 | F16: 0.13 | G16: 0.1 | H16: 0.1 | I16: 0.17
C18: UNITS | D18: 500 | F18: Incentive | G18: =INDEX(D7:I16,MATCH(D18,C7:C16,0),MATCH(D19,D6:I6,0)) -> 0.16
C19: SALESMAN | D19: 5

Sheet Day-5
E2: Approximate Match
C3: INDEX(D7:I16,MATCH(D18,C7:C16,1),MATCH(D19,D6:I6,1))
D5: SALESMAN
D6: 1 | E6: 2 | F6: 3 | G6: 4 | H6: 5 | I6: 6 | L6: 0.01
B7: UNITS | C7: 100 | D7: 0.05 | E7: 0.06 | F7: 0.07 | G7: 0.08 | H7: 0.09 | I7: 0.1
C8: 200 | D8: 0.06 | E8: 0.07 | F8: 0.08 | G8: 0.09 | H8: 0.1 | I8: 0.11
C9: 300 | D9: 0.07 | E9: 0.08 | F9: 0.09 | G9: 0.1 | H9: 0.11 | I9: 0.12
C10: 400 | D10: 0.08 | E10: 0.09 | F10: 0.1 | G10: 0.11 | H10: 0.12 | I10: 0.13
C11: 500 | D11: 0.09 | E11: 0.1 | F11: 0.11 | G11: 0.12 | H11: 0.13 | I11: 0.14
C12: 600 | D12: 0.1 | E12: 0.11 | F12: 0.12 | G12: 0.13 | H12: 0.14 | I12: 0.15
C13: 700 | D13: 0.11 | E13: 0.12 | F13: 0.13 | G13: 0.14 | H13: 0.15 | I13: 0.16
C14: 800 | D14: 0.12 | E14: 0.13 | F14: 0.14 | G14: 0.15 | H14: 0.16 | I14: 0.17
C15: 900 | D15: 0.13 | E15: 0.14 | F15: 0.15 | G15: 0.16 | H15: 0.17 | I15: 0.18
C16: 1000 | D16: 0.14 | E16: 0.15 | F16: 0.16 | G16: 0.17 | H16: 0.18 | I16: 0.19
C18: UNITS | D18: 455 | F18: Incentive | G18: =INDEX(D7:I16,MATCH(D18,C7:C16,1),MATCH(D19,D6:I6,1)) -> 0.12
C19: SALESMAN | D19: 5

Sheet Day-6
C2: Sum A Row based On A Condition
B3: INDEX(D7:I16,MATCH(D18,C7:C16,1),MATCH(D19,D6:I6,1))
C5: STORE1 | D5: STORE2 | E5: STORE3 | F5: STORE4 | G5: STORE5 | H5: STORE6 | I5: TOTAL
B6: BLACKBERRY | C6: 81 | D6: 92 | E6: 94 | F6: 65 | G6: 82 | H6: 60 | I6: =SUM(C6:H6) -> 474
B7: NOKIA | C7: 90 | D7: 63 | E7: 89 | F7: 86 | G7: 51 | H7: 56 | I7: =SUM(C7:H7) -> 435
B8: SAMSUNG | C8: 53 | D8: 67 | E8: 79 | F8: 93 | G8: 83 | H8: 67 | I8: =SUM(C8:H8) -> 442
B9: LG | C9: 97 | D9: 55 | E9: 51 | F9: 68 | G9: 80 | H9: 89 | I9: =SUM(C9:H9) -> 440
B10: SONY | C10: 56 | D10: 67 | E10: 93 | F10: 71 | G10: 98 | H10: 99 | I10: =SUM(C10:H10) -> 484
B11: MOTOROLA | C11: 54 | D11: 51 | E11: 71 | F11: 67 | G11: 98 | H11: 68 | I11: =SUM(C11:H11) -> 409
B12: DELL | C12: 86 | D12: 70 | E12: 59 | F12: 80 | G12: 96 | H12: 61 | I12: =SUM(C12:H12) -> 452
B13: ACER | C13: 95 | D13: 88 | E13: 54 | F13: 51 | G13: 90 | H13: 84 | I13: =SUM(C13:H13) -> 462
B14: HTC | C14: 98 | D14: 53 | E14: 80 | F14: 97 | G14: 85 | H14: 56 | I14: =SUM(C14:H14) -> 469
B16: SAMSUNG | C16: =SUM(INDEX(C6:H14,MATCH(B16,B6:B14,0),)) -> 442

Sheet Day-7
B2: Index And Match 9 Sum A Column Based On A Condition
B3: SUM(INDEX(C6:H14,,MATCH(B16,C5:H5,0)))
C5: STORE1 | D5: STORE2 | E5: STORE3 | F5: STORE4 | G5: STORE5 | H5: STORE6
B6: BLACKBERRY | C6: 81 | D6: 92 | E6: 94 | F6: 65 | G6: 82 | H6: 60
B7: NOKIA | C7: 90 | D7: 63 | E7: 89 | F7: 86 | G7: 51 | H7: 56
B8: SAMSUNG | C8: 53 | D8: 67 | E8: 79 | F8: 93 | G8: 83 | H8: 67
B9: LG | C9: 97 | D9: 55 | E9: 51 | F9: 68 | G9: 80 | H9: 89
B10: SONY | C10: 56 | D10: 67 | E10: 93 | F10: 71 | G10: 98 | H10: 99
B11: MOTOROLA | C11: 54 | D11: 51 | E11: 71 | F11: 67 | G11: 98 | H11: 68
B12: DELL | C12: 86 | D12: 70 | E12: 59 | F12: 80 | G12: 96 | H12: 61
B13: ACER | C13: 95 | D13: 88 | E13: 54 | F13: 51 | G13: 90 | H13: 84
B14: HTC | C14: 98 | D14: 53 | E14: 80 | F14: 97 | G14: 85 | H14: 56
B15: TOTAL | C15: =SUM(C6:C14) -> 710 | D15: =SUM(D6:D14) -> 606 | E15: =SUM(E6:E14) -> 670 | F15: =SUM(F6:F14) -> 678 | G15: =SUM(G6:G14) -> 763 | H15: =SUM(H6:H14) -> 640
B17: STORE6 | C17: =SUM(INDEX(C6:H14,,MATCH(B17,C5:H5,0))) -> 640

Sheet Day-8
B2: Index And Match With Min Formula Lookup The Lowest Value
B3: INDEX($C$5:$H$5,MATCH(I6,C6:H6,0))
C5: STORE1 | D5: STORE2 | E5: STORE3 | F5: STORE4 | G5: STORE5 | H5: STORE6 | I5: LOWEST AMOUNT | J5: LOWEST SELING STORE
B6: BLACKBERRY | C6: 53 | D6: 54 | E6: 56 | F6: 81 | G6: 86 | H6: 90 | I6: =MIN(C6:H6) -> 53 | J6: =INDEX($C$5:$H$5,MATCH(I6,C6:H6,0)) -> STORE1
B7: NOKIA | C7: 51 | D7: 53 | E7: 55 | F7: 40 | G7: 67 | H7: 67 | I7: =MIN(C7:H7) -> 40 | J7: =INDEX($C$5:$H$5,MATCH(I7,C7:H7,0)) -> STORE4
B8: SAMSUNG | C8: 51 | D8: 54 | E8: 30 | F8: 71 | G8: 79 | H8: 80 | I8: =MIN(C8:H8) -> 30 | J8: =INDEX($C$5:$H$5,MATCH(I8,C8:H8,0)) -> STORE3
B9: LG | C9: 51 | D9: 29 | E9: 67 | F9: 68 | G9: 71 | H9: 80 | I9: =MIN(C9:H9) -> 29 | J9: =INDEX($C$5:$H$5,MATCH(I9,C9:H9,0)) -> STORE2
B10: SONY | C10: 51 | D10: 80 | E10: 82 | F10: 83 | G10: 10 | H10: 90 | I10: =MIN(C10:H10) -> 10 | J10: =INDEX($C$5:$H$5,MATCH(I10,C10:H10,0)) -> STORE5
B11: MOTOROLA | C11: 56 | D11: 56 | E11: 60 | F11: 61 | G11: 67 | H11: 68 | I11: =MIN(C11:H11) -> 56 | J11: =INDEX($C$5:$H$5,MATCH(I11,C11:H11,0)) -> STORE1
B12: DELL | C12: 51 | D12: 65 | E12: 67 | F12: 68 | G12: 71 | H12: 44 | I12: =MIN(C12:H12) -> 44 | J12: =INDEX($C$5:$H$5,MATCH(I12,C12:H12,0)) -> STORE6
B13: ACER | C13: 51 | D13: 29 | E13: 82 | F13: 83 | G13: 85 | H13: 90 | I13: =MIN(C13:H13) -> 29 | J13: =INDEX($C$5:$H$5,MATCH(I13,C13:H13,0)) -> STORE2
B14: HTC | C14: 56 | D14: 56 | E14: 60 | F14: 33 | G14: 67 | H14: 68 | I14: =MIN(C14:H14) -> 33 | J14: =INDEX($C$5:$H$5,MATCH(I14,C14:H14,0)) -> STORE4

Sheet Day-9
B2: Index And Match With Max Formula Lookup The Highest Value
B3: INDEX($C$5:$H$5,MATCH(I6,C6:H6,0))
C5: STORE1 | D5: STORE2 | E5: STORE3 | F5: STORE4 | G5: STORE5 | H5: STORE6 | I5: HIGHEST AMOUNT | J5: HIGHEST SELING STORE
B6: BLACKBERRY | C6: 53 | D6: 54 | E6: 56 | F6: 81 | G6: 222 | H6: 90 | I6: =MAX(C6:H6) -> 222 | J6: =INDEX($C$5:$H$5,MATCH(I6,C6:H6,0)) -> STORE5
B7: NOKIA | C7: 51 | D7: 53 | E7: 55 | F7: 40 | G7: 67 | H7: 67 | I7: =MAX(C7:H7) -> 67 | J7: =INDEX($C$5:$H$5,MATCH(I7,C7:H7,0)) -> STORE5
B8: SAMSUNG | C8: 51 | D8: 54 | E8: 30 | F8: 71 | G8: 79 | H8: 80 | I8: =MAX(C8:H8) -> 80 | J8: =INDEX($C$5:$H$5,MATCH(I8,C8:H8,0)) -> STORE6
B9: LG | C9: 51 | D9: 29 | E9: 67 | F9: 222 | G9: 71 | H9: 80 | I9: =MAX(C9:H9) -> 222 | J9: =INDEX($C$5:$H$5,MATCH(I9,C9:H9,0)) -> STORE4
B10: SONY | C10: 111 | D10: 80 | E10: 82 | F10: 83 | G10: 10 | H10: 90 | I10: =MAX(C10:H10) -> 111 | J10: =INDEX($C$5:$H$5,MATCH(I10,C10:H10,0)) -> STORE1
B11: MOTOROLA | C11: 56 | D11: 56 | E11: 201 | F11: 61 | G11: 67 | H11: 68 | I11: =MAX(C11:H11) -> 201 | J11: =INDEX($C$5:$H$5,MATCH(I11,C11:H11,0)) -> STORE3
B12: DELL | C12: 51 | D12: 99 | E12: 67 | F12: 68 | G12: 71 | H12: 44 | I12: =MAX(C12:H12) -> 99 | J12: =INDEX($C$5:$H$5,MATCH(I12,C12:H12,0)) -> STORE2
B13: ACER | C13: 51 | D13: 29 | E13: 82 | F13: 83 | G13: 85 | H13: 90 | I13: =MAX(C13:H13) -> 90 | J13: =INDEX($C$5:$H$5,MATCH(I13,C13:H13,0)) -> STORE6
B14: HTC | C14: 56 | D14: 56 | E14: 60 | F14: 33 | G14: 67 | H14: 22 | I14: =MAX(C14:H14) -> 67 | J14: =INDEX($C$5:$H$5,MATCH(I14,C14:H14,0)) -> STORE5

Sheet Day-10
A1: EXAMPLE-1
A2: INDEX & MATCH FORMULA 12 REFERENCE & AREA TO LOOKUP ANS FROM 3 DIFFERENT TABLES
A3: INDEX(($B$7:$B$11,$B$15:$B$19,$B$22:$B$26),MATCH(G7,$A$7:$A$11,1),,VLOOKUP(F7,$A$28:$B$30,2,0))
B6: SAMSUNG | C6: DISCOUNT | E6: 0.01 | G6: Item Name | H6: Sale | I6: Discount
B7: 500 | C7: 0.01 | G7: Samsung | H7: 2851 | I7: =INDEX(($C$7:$C$11,$C$15:$C$19,$C$22:$C$26),MATCH(H7,$B$7:$B$11,1),,VLOOKUP(G7,$B$28:$C$30,2,0)) -> 0.03
B8: 1000 | C8: 0.02 | G8: Blackberry | H8: 4047 | I8: =INDEX(($C$7:$C$11,$C$15:$C$19,$C$22:$C$26),MATCH(H8,$B$7:$B$11,1),,VLOOKUP(G8,$B$28:$C$30,2,0)) -> 0.06
B9: 2000 | C9: 0.03 | G9: Apple | H9: 4461 | I9: =INDEX(($C$7:$C$11,$C$15:$C$19,$C$22:$C$26),MATCH(H9,$B$7:$B$11,1),,VLOOKUP(G9,$B$28:$C$30,2,0)) -> 0.08
B10: 3000 | C10: 0.04 | G10: Blackberry | H10: 3256 | I10: =INDEX(($C$7:$C$11,$C$15:$C$19,$C$22:$C$26),MATCH(H10,$B$7:$B$11,1),,VLOOKUP(G10,$B$28:$C$30,2,0)) -> 0.06
B11: 5000 | C11: 0.05 | G11: Apple | H11: 2178 | I11: =INDEX(($C$7:$C$11,$C$15:$C$19,$C$22:$C$26),MATCH(H11,$B$7:$B$11,1),,VLOOKUP(G11,$B$28:$C$30,2,0)) -> 0.07
G12: Apple | H12: 3374 | I12: =INDEX(($C$7:$C$11,$C$15:$C$19,$C$22:$C$26),MATCH(H12,$B$7:$B$11,1),,VLOOKUP(G12,$B$28:$C$30,2,0)) -> 0.08
G13: Samsung | H13: 4682 | I13: =INDEX(($C$7:$C$11,$C$15:$C$19,$C$22:$C$26),MATCH(H13,$B$7:$B$11,1),,VLOOKUP(G13,$B$28:$C$30,2,0)) -> 0.04
B14: BLACKBERRY | C14: DISCOUNT | G14: Blackberry | H14: 2684 | I14: =INDEX(($C$7:$C$11,$C$15:$C$19,$C$22:$C$26),MATCH(H14,$B$7:$B$11,1),,VLOOKUP(G14,$B$28:$C$30,2,0)) -> 0.05
B15: 500 | C15: 0.03 | G15: Samsung | H15: 1317 | I15: =INDEX(($C$7:$C$11,$C$15:$C$19,$C$22:$C$26),MATCH(H15,$B$7:$B$11,1),,VLOOKUP(G15,$B$28:$C$30,2,0)) -> 0.02
B16: 1000 | C16: 0.04 | G16: Apple | H16: 1068 | I16: =INDEX(($C$7:$C$11,$C$15:$C$19,$C$22:$C$26),MATCH(H16,$B$7:$B$11,1),,VLOOKUP(G16,$B$28:$C$30,2,0)) -> 0.06
B17: 2000 | C17: 0.05 | G17: Blackberry | H17: 2498 | I17: =INDEX(($C$7:$C$11,$C$15:$C$19,$C$22:$C$26),MATCH(H17,$B$7:$B$11,1),,VLOOKUP(G17,$B$28:$C$30,2,0)) -> 0.05
B18: 3000 | C18: 0.06 | G18: Apple | H18: 4230 | I18: =INDEX(($C$7:$C$11,$C$15:$C$19,$C$22:$C$26),MATCH(H18,$B$7:$B$11,1),,VLOOKUP(G18,$B$28:$C$30,2,0)) -> 0.08
B19: 5000 | C19: 0.07 | G19: Samsung | H19: 2295 | I19: =INDEX(($C$7:$C$11,$C$15:$C$19,$C$22:$C$26),MATCH(H19,$B$7:$B$11,1),,VLOOKUP(G19,$B$28:$C$30,2,0)) -> 0.03
G20: Apple | H20: 1805 | I20: =INDEX(($C$7:$C$11,$C$15:$C$19,$C$22:$C$26),MATCH(H20,$B$7:$B$11,1),,VLOOKUP(G20,$B$28:$C$30,2,0)) -> 0.06
B21: APPLE | C21: DISCOUNT | G21: Apple | H21: 520 | I21: =INDEX(($C$7:$C$11,$C$15:$C$19,$C$22:$C$26),MATCH(H21,$B$7:$B$11,1),,VLOOKUP(G21,$B$28:$C$30,2,0)) -> 0.05
B22: 500 | C22: 0.05 | G22: Blackberry | H22: 1913 | I22: =INDEX(($C$7:$C$11,$C$15:$C$19,$C$22:$C$26),MATCH(H22,$B$7:$B$11,1),,VLOOKUP(G22,$B$28:$C$30,2,0)) -> 0.04
B23: 1000 | C23: 0.06 | G23: Samsung | H23: 1618 | I23: =INDEX(($C$7:$C$11,$C$15:$C$19,$C$22:$C$26),MATCH(H23,$B$7:$B$11,1),,VLOOKUP(G23,$B$28:$C$30,2,0)) -> 0.02
B24: 2000 | C24: 0.07
B25: 3000 | C25: 0.08
B26: 5000 | C26: 0.09
B28: Samsung | C28: 1
B29: Blackberry | C29: 2
B30: Apple | C30: 3
A33: EXAMPLE-2
A34: INDEX & MATCH FORMULA 12 REFERENCE & AREA TO LOOKUP ANS FROM 3 DIFFERENT TABLES
A35: INDEX(($B$39:$B$43,$C$39:$C$43,$D$39:$D$43),MATCH(J39,$A$39:$A$43,1),,VLOOKUP(I39,$B$48:$C$50,2,0))
A38: SAMSUNG | B38: SAMSUNG | C38: BLACKBERRY | D38: APPLE | F38: 0.01 | I38: Item Name | J38: Sale | K38: Discount
A39: 500 | B39: 0.01 | C39: 0.03 | D39: 0.05 | I39: Samsung | J39: 2851 | K39: =INDEX(($B$39:$B$43,$C$39:$C$43,$D$39:$D$43),MATCH(J39,$A$39:$A$43,1),,VLOOKUP(I39,$B$48:$C$50,2,0)) -> 0.03
A40: 1000 | B40: 0.02 | C40: 0.04 | D40: 0.06 | I40: Blackberry | J40: 4047 | K40: =INDEX(($B$39:$B$43,$C$39:$C$43,$D$39:$D$43),MATCH(J40,$A$39:$A$43,1),,VLOOKUP(I40,$B$48:$C$50,2,0)) -> 0.06
A41: 2000 | B41: 0.03 | C41: 0.05 | D41: 0.07 | I41: Apple | J41: 4461 | K41: =INDEX(($B$39:$B$43,$C$39:$C$43,$D$39:$D$43),MATCH(J41,$A$39:$A$43,1),,VLOOKUP(I41,$B$48:$C$50,2,0)) -> 0.08
A42: 3000 | B42: 0.04 | C42: 0.06 | D42: 0.08 | I42: Blackberry | J42: 3256 | K42: =INDEX(($B$39:$B$43,$C$39:$C$43,$D$39:$D$43),MATCH(J42,$A$39:$A$43,1),,VLOOKUP(I42,$B$48:$C$50,2,0)) -> 0.06
A43: 5000 | B43: 0.05 | C43: 0.07 | D43: 0.09 | I43: Apple | J43: 2178 | K43: =INDEX(($B$39:$B$43,$C$39:$C$43,$D$39:$D$43),MATCH(J43,$A$39:$A$43,1),,VLOOKUP(I43,$B$48:$C$50,2,0)) -> 0.07
I44: Apple | J44: 3374 | K44: =INDEX(($B$39:$B$43,$C$39:$C$43,$D$39:$D$43),MATCH(J44,$A$39:$A$43,1),,VLOOKUP(I44,$B$48:$C$50,2,0)) -> 0.08
I45: Samsung | J45: 4682 | K45: =INDEX(($B$39:$B$43,$C$39:$C$43,$D$39:$D$43),MATCH(J45,$A$39:$A$43,1),,VLOOKUP(I45,$B$48:$C$50,2,0)) -> 0.04
I46: Blackberry | J46: 2684 | K46: =INDEX(($B$39:$B$43,$C$39:$C$43,$D$39:$D$43),MATCH(J46,$A$39:$A$43,1),,VLOOKUP(I46,$B$48:$C$50,2,0)) -> 0.05
I47: Samsung | J47: 1317 | K47: =INDEX(($B$39:$B$43,$C$39:$C$43,$D$39:$D$43),MATCH(J47,$A$39:$A$43,1),,VLOOKUP(I47,$B$48:$C$50,2,0)) -> 0.02
...

Sheet Day-11
B1: EXAMPLE-1 | H1: Date | I1: 41039
B2: $I$1=$C4
B3: Product | C3: Date | D3: Units | E3: Sold Name | G3: Formula
B4: Honda | C4: 41028 | D4: 5 | E4: Superman | G4: =$I$1=$C4 -> FALSE
B5: Suzuki | C5: 41029 | D5: 5 | E5: Heman | G5: =$I$1=$C5 -> FALSE
B6: Toyota | C6: 41030 | D6: 3 | E6: Batman | G6: =$I$1=$C6 -> FALSE
B7: Mercedes | C7: 41031 | D7: 3 | E7: Spiderman | G7: =$I$1=$C7 -> FALSE
B8: BMW | C8: 41032 | D8: 2 | E8: Thor | G8: =$I$1=$C8 -> FALSE
B9: Jaguar | C9: 41033 | D9: 5 | E9: Iron man | G9: =$I$1=$C9 -> FALSE
B10: Honda | C10: 41034 | D10: 5 | E10: Superman | G10: =$I$1=$C10 -> FALSE
B11: Toyota | C11: 41035 | D11: 3 | E11: Heman | G11: =$I$1=$C11 -> FALSE
B12: Jaguar | C12: 41036 | D12: 7 | E12: Batman | G12: =$I$1=$C12 -> FALSE
B13: Suzuki | C13: 41037 | D13: 4 | E13: Spiderman | G13: =$I$1=$C13 -> FALSE
B14: Mercedes | C14: 41038 | D14: 6 | E14: Thor | G14: =$I$1=$C14 -> FALSE
B15: Honda | C15: 41039 | D15: 6 | E15: Iron man | G15: =$I$1=$C15 -> TRUE
... B17: BMW | C17: 41041 | D17: 3 | E17: Thor | G17: =$I$1=$C17 -> FALSE
B21: EXAMPLE-2 | H21: Date | I21: 41034
B22: $I$1=$C24
B23: Product | C23: Date | D23: Units | E23: Sold Name | G23: Formula
B24: Honda | C24: 41028 | D24: 5 | E24: Superman | G24: =$I$1=$C24 -> FALSE
B25: Suzuki | C25: 41029 | D25: 5 | E25: Heman | G25: =$I$1=$C25 -> FALSE
B26: Toyota | C26: 41030 | D26: 3 | E26: Batman | G26: =$I$1=$C26 -> FALSE
B27: Mercedes | C27: 41031 | D27: 3 | E27: Spiderman | G27: =$I$1=$C27 -> FALSE
B28: BMW | C28: 41032 | D28: 2 | E28: Thor | G28: =$I$1=$C28 -> FALSE
B29: Jaguar | C29: 41033 | D29: 5 | E29: Iron man | G29: =$I$1=$C29 -> FALSE
B30: Honda | C30: 41034 | D30: 5 | E30: Superman | G30: =$I$1=$C30 -> FALSE
B31: Toyota | C31: 41035 | D31: 3 | E31: Heman | G31: =$I$1=$C31 -> FALSE
B32: Jaguar | C32: 41036 | D32: 7 | E32: Batman | G32: =$I$1=$C32 -> FALSE
B33: Suzuki | C33: 41037 | D33: 4 | E33: Spiderman | G33: =$I$1=$C33 -> FALSE
B34: Mercedes | C34: 41038 | D34: 6 | E34: Thor | G34: =$I$1=$C34 -> FALSE
B35: Honda | C35: 41039 | D35: 6 | E35: Iron man | G35: =$I$1=$C35 -> TRUE
... B37: BMW | C37: 41041 | D37: 3 | E37: Thor | G37: =$I$1=$C37 -> FALSE

Sheet Day-12
B1: $B$4:$E$17 | G1: Header | H1: Sold Name
B3: Product | C3: Date | D3: Units | E3: Sold Name
B4: Honda | C4: 41028 | D4: 5 | E4: Superman
B5: Suzuki | C5: 41029 | D5: 5 | E5: Heman
B6: Toyota | C6: 41030 | D6: 3 | E6: Batman
B7: Mercedes | C7: 41031 | D7: 3 | E7: Spiderman
B8: BMW | C8: 41032 | D8: 2 | E8: Thor
B9: Jaguar | C9: 41033 | D9: 5 | E9: Iron man
B10: Honda | C10: 41034 | D10: 5 | E10: Superman
B11: Toyota | C11: 41035 | D11: 3 | E11: Heman
B12: Jaguar | C12: 41036 | D12: 7 | E12: Batman
B13: Suzuki | C13: 41037 | D13: 4 | E13: Spiderman
B14: Mercedes | C14: 41038 | D14: 6 | E14: Thor
B15: Honda | C15: 41039 | D15: 6 | E15: Iron man
... B17: BMW | C17: 41041 | D17: 3 | E17: Thor

Sheet Day-13
C1: VLOOKUP
C2: VLOOKUP(C10,$C$3:$J$8,5,0)
C4: Name | D4: 45017 | E4: 45018 | F4: 45019 | G4: 45020 | H4: 45021 | I4: 45022 | J4: 45023
C5: Apple | D5: 65 | E5: 77 | F5: 95 | G5: 34 | H5: 46 | I5: 55 | J5: 61
C6: Banana | D6: 31 | E6: 75 | F6: 36 | G6: 91 | H6: 25 | I6: 38 | J6: 40
C7: Pineapple | D7: 61 | E7: 62 | F7: 29 | G7: 77 | H7: 65 | I7: 84 | J7: 58
C8: Grapes | D8: 56 | E8: 98 | F8: 25 | G8: 31 | H8: 94 | I8: 45 | J8: 22
C9: Mango | D9: 58 | E9: 27 | F9: 20 | G9: 74 | H9: 96 | I9: 67 | J9: 70
C11: Apple | D11: =VLOOKUP(C11,$C$4:$J$9,5,0) -> 34
C12: Banana | D12: =VLOOKUP(C12,$C$4:$J$9,5,0) -> 91

Sheet Day-14
C1: VLOOKUP WITH DIFFERENT SHEETS
C2: VLOOKUP(C6,Vlookup_data!C4:I17,2,0)
C5: Student | D5: Eng | E5: Maths | F5: Science
C6: Jhon | D6: =VLOOKUP(C6,'Data-1'!C4:I17,2,0) -> 51 | E6: =VLOOKUP(D6,'Data-1'!D4:J17,2,0) -> 96 | F6: =VLOOKUP(E6,'Data-1'!E4:K17,2,0) -> 31
C7: Mike | D7: =VLOOKUP(C7,'Data-1'!C5:I18,2,0) -> 49 | E7: =VLOOKUP(D7,'Data-1'!D5:J18,2,0) -> 43 | F7: =VLOOKUP(E7,'Data-1'!E5:K18,2,0) -> 77
C8: Aman | D8: =VLOOKUP(C8,'Data-1'!C6:I19,2,0) -> 56 | E8: =VLOOKUP(D8,'Data-1'!D6:J19,2,0) -> 49 | F8: =VLOOKUP(E8,'Data-1'!E6:K19,2,0) -> 47
C9: Rajeev | D9: =VLOOKUP(C9,'Data-1'!C7:I20,2,0) -> 30 | E9: =VLOOKUP(D9,'Data-1'!D7:J20,2,0) -> 54 | F9: =VLOOKUP(E9,'Data-1'!E7:K20,2,0) -> 45
C10: Ashish | D10: =VLOOKUP(C10,'Data-1'!C8:I21,2,0) -> 35 | E10: =VLOOKUP(D10,'Data-1'!D8:J21,2,0) -> 86 | F10: =VLOOKUP(E10,'Data-1'!E8:K21,2,0) -> 43
C11: Charlie | D11: =VLOOKUP(C11,'Data-1'!C9:I22,2,0) -> 81 | E11: =VLOOKUP(D11,'Data-1'!D9:J22,2,0) -> 30 | F11: =VLOOKUP(E11,'Data-1'!E9:K22,2,0) -> 45
C12: Quarrat | D12: =VLOOKUP(C12,'Data-1'!C10:I23,2,0) -> 62 | E12: =VLOOKUP(D12,'Data-1'!D10:J23,2,0) -> 74 | F12: =VLOOKUP(E12,'Data-1'!E10:K23,2,0) -> 53
C13: Raju | D13: =VLOOKUP(C13,'Data-1'!C11:I24,2,0) -> 71 | E13: =VLOOKUP(D13,'Data-1'!D11:J24,2,0) -> 73 | F13: =VLOOKUP(E13,'Data-1'!E11:K24,2,0) -> 97
C14: Janice | D14: =VLOOKUP(C14,'Data-1'!C12:I25,2,0) -> 91 | E14: =VLOOKUP(D14,'Data-1'!D12:J25,2,0) -> 64 | F14: =VLOOKUP(E14,'Data-1'!E12:K25,2,0) -> 52
C15: Kalvin | D15: =VLOOKUP(C15,'Data-1'!C13:I26,2,0) -> 42 | E15: =VLOOKUP(D15,'Data-1'!D13:J26,2,0) -> 30 | F15: =VLOOKUP(E15,'Data-1'!E13:K26,2,0) -> 56
C16: Douglas | D16: =VLOOKUP(C16,'Data-1'!C14:I27,2,0) -> 96 | E16: =VLOOKUP(D16,'Data-1'!D14:J27,2,0) -> 30 | F16: =VLOOKUP(E16,'Data-1'!E14:K27,2,0) -> 64
C17: Munni | D17: =VLOOKUP(C17,'Data-1'!C15:I28,2,0) -> 75 | E17: =VLOOKUP(D17,'Data-1'!D15:J28,2,0) -> 35 | F17: =VLOOKUP(E17,'Data-1'!E15:K28,2,0) -> 68
... C19: Shalu | D19: =VLOOKUP(C19,'Data-1'!C17:I30,2,0) -> 83 | E19: =VLOOKUP(D19,'Data-1'!D17:J30,2,0) -> 95 | F19: =VLOOKUP(E19,'Data-1'!E17:K30,2,0) -> 71

Sheet Data-1
C1: Student)_Data
C3: Student | D3: Eng | E3: Maths | F3: Science | G3: History | H3: Geography | I3: French
C4: Jhon | D4: 51 | E4: 96 | F4: 31 | G4: 97 | H4: 69 | I4: 84
C5: Mike | D5: 49 | E5: 43 | F5: 77 | G5: 38 | H5: 34 | I5: 81
C6: Aman | D6: 56 | E6: 49 | F6: 47 | G6: 93 | H6: 97 | I6: 99
C7: Rajeev | D7: 30 | E7: 54 | F7: 45 | G7: 62 | H7: 80 | I7: 90
C8: Ashish | D8: 35 | E8: 86 | F8: 43 | G8: 54 | H8: 81 | I8: 78
C9: Charlie | D9: 81 | E9: 30 | F9: 45 | G9: 79 | H9: 36 | I9: 99
C10: Quarrat | D10: 62 | E10: 74 | F10: 53 | G10: 92 | H10: 96 | I10: 85
C11: Raju | D11: 71 | E11: 73 | F11: 97 | G11: 93 | H11: 58 | I11: 32
C12: Janice | D12: 91 | E12: 64 | F12: 52 | G12: 51 | H12: 90 | I12: 77
C13: Kalvin | D13: 42 | E13: 30 | F13: 56 | G13: 90 | H13: 66 | I13: 53
C14: Douglas | D14: 96 | E14: 30 | F14: 64 | G14: 74 | H14: 46 | I14: 71
C15: Munni | D15: 75 | E15: 35 | F15: 68 | G15: 62 | H15: 47 | I15: 40
... C17: Shalu | D17: 83 | E17: 95 | F17: 71 | G17: 46 | H17: 58 | I17: 58

Sheet Day-15
B1: Vlookup Exact and Approx Match Hindi
B4: ID Number | C4: Name | G4: Exact = O | H4: Approx = 1
B5: 5 | C5: Karan | G5: Conditions To Test
B6: 10 | C6: Rambo | G6: 1.Below the minimum
B7: 15 | C7: Superman | G7: 2.Greater then the highest
B8: 20 | C8: Hulk | G8: 3.Within the range
G9: 4.Exact
B12: ID Number | C12: Name
B13: 5 | C13: =VLOOKUP(B13,B4:C8,2,0) -> Karan
B14: 3 | C14: =VLOOKUP(B14,B4:C8,2,1) -> #N/A
B15: 21 | C15: =VLOOKUP(B15,B5:C9,2,1) -> Hulk
B16: 12 | C16: =VLOOKUP(B16,B6:C10,2,1) -> Rambo

Sheet Day-16
C2: Excel - Vlookup With Min
C3: VLOOKUP(MIN(F6:F11),F5:H11,3,0)
C5: Marks in English | D5: Marks in History | E5: Total Marks | F5: Marks Achieved | G5: % Marks | H5: Name
C6: 86 | D6: 88 | E6: 200 | F6: =SUM(C6:D6) -> 174 | G6: =(F6/E6*100)*0.01 -> 0.87 | H6: Alan | J6: 0.01
C7: 99 | D7: 86 | E7: 200 | F7: =SUM(C7:D7) -> 185 | G7: =(F7/E7*100)*0.01 -> 0.925 | H7: John
C8: 59 | D8: 78 | E8: 200 | F8: =SUM(C8:D8) -> 137 | G8: =(F8/E8*100)*0.01 -> 0.685 | H8: Mike
C9: 59 | D9: 82 | E9: 200 | F9: =SUM(C9:D9) -> 141 | G9: =(F9/E9*100)*0.01 -> 0.705 | H9: S Derman
C10: 69 | D10: 47 | E10: 200 | F10: =SUM(C10:D10) -> 116 | G10: =(F10/E10*100)*0.01 -> 0.58 | H10: Bob
C11: 99.99 | D11: 40 | E11: 200 | F11: =SUM(C11:D11) -> 139.99 | G11: =(F11/E11*100)*0.01 -> 0.69995 | H11: Karol
D13: Lowest Marks Achived | G13: Name | H13: =VLOOKUP(MIN(F6:F11),F5:H11,3,0) -> Bob | I13: =H13 -> Bob

Sheet Day-17
C2: Excel - Vlookup With Max
C3: VLOOKUP(MAX(D6:D11),D5:H11,5,0)
C5: Marks in English | D5: Marks in History | E5: Total Marks | F5: Marks Achieved | G5: % Marks | H5: Name
C6: 86 | D6: 88 | E6: 200 | F6: =SUM(C6:D6) -> 174 | G6: =(F6/E6*100)*0.01 -> 0.87 | H6: Alan | J6: 0.01
C7: 99 | D7: 86 | E7: 200 | F7: =SUM(C7:D7) -> 185 | G7: =(F7/E7*100)*0.01 -> 0.925 | H7: John
C8: 59 | D8: 96 | E8: 200 | F8: =SUM(C8:D8) -> 155 | G8: =(F8/E8*100)*0.01 -> 0.775 | H8: Mike
C9: 59 | D9: 82 | E9: 200 | F9: =SUM(C9:D9) -> 141 | G9: =(F9/E9*100)*0.01 -> 0.705 | H9: SDerman
C10: 69 | D10: 88 | E10: 200 | F10: =SUM(C10:D10) -> 157 | G10: =(F10/E10*100)*0.01 -> 0.785 | H10: Bob
C11: 99.99 | D11: 40 | E11: 200 | F11: =SUM(C11:D11) -> 139.99 | G11: =(F11/E11*100)*0.01 -> 0.69995 | H11: Karol
D13: Highest Marks in History | G13: Name | H13: =VLOOKUP(MAX(D6:D11),D5:H11,5,0) -> Mike | I13: =H13 -> Mike

Sheet Day-18
B4: Names | C4: Marks | G4: Name | H4: Marks
B5: Heman | C5: 44 | G5: Superman | H5: =VLOOKUP(G5,B4:C14,2,0) -> 20
B6: Superman | C6: 20 | G6: Ram | H6: =IFERROR(VLOOKUP(G6,B5:C15,2,0),"")
B7: Magneto | C7: 25 | G7: Modi | H7: =IFERROR(VLOOKUP(G7,B6:C16,2,0),"I will be Back") -> I will be Back
B8: Hulk | C8: 40
B9: Thor | C9: 18
B10: Munni | C10: 36
B11: Sheela | C11: 45
B12: Kim K | C12: 46
B13: Paris Hilton | C13: 45

Sheet Day-19
C2: VLOOKUP MULTIPLE RESULTS FOR SINGLE QUERY AT ONCE
C3: VLOOKUP($C$16,$C$3:$J$12,COLUMNS($C3:D3))
C4: Name | D4: Subject1 | E4: Subject2 | F4: Subject3 | G4: Subject4 | H4: Subject5 | I4: Subject6 | J4: Subject7
C5: Heman | D5: 54 | E5: 69 | F5: 78 | G5: 70 | H5: 45 | I5: 68 | J5: 49
C6: Superman | D6: 80 | E6: 95 | F6: 97 | G6: 67 | H6: 62 | I6: 54 | J6: 47
C7: Magneto | D7: 80 | E7: 77 | F7: 91 | G7: 70 | H7: 82 | I7: 57 | J7: 62
C8: Hulk | D8: 69 | E8: 97 | F8: 72 | G8: 70 | H8: 62 | I8: 83 | J8: 93
C9: Thor | D9: 61 | E9: 49 | F9: 78 | G9: 55 | H9: 69 | I9: 67 | J9: 82
C10: Munni | D10: 59 | E10: 84 | F10: 54 | G10: 61 | H10: 64 | I10: 76 | J10: 42
C11: Sheela | D11: 79 | E11: 81 | F11: 72 | G11: 93 | H11: 69 | I11: 82 | J11: 52
C12: Kim K | D12: 92 | E12: 75 | F12: 73 | G12: 47 | H12: 42 | I12: 78 | J12: 92
C13: Paris Hilton | D13: 71 | E13: 90 | F13: 75 | G13: 66 | H13: 75 | I13: 73 | J13: 71
C16: Name | D16: Subject1 | E16: Subject2 | F16: Subject3 | G16: Subject4 | H16: Subject5 | I16: Subject6 | J16: Subject7
C17: Thor | D17: =IFERROR(VLOOKUP($C$17,$C$4:$J$13,COLUMNS($C4:D4)),"Name Not Avaible") -> 71 | E17: =IFERROR(VLOOKUP($C$17,$C$4:$J$13,COLUMNS($C4:E4)),"Name Not Avaible") -> 90 | F17: =IFERROR(VLOOKUP($C$17,$C$4:$J$13,COLUMNS($C4:F4)),"Name Not Avaible") -> 75 | G17: =IFERROR(VLOOKUP($C$17,$C$4:$J$13,COLUMNS($C4:G4)),"Name Not Avaible") -> 66 | H17: =IFERROR(VLOOKUP($C$17,$C$4:$J$13,COLUMNS($C4:H4)),"Name Not Avaible") -> 75 | I17: =IFERROR(VLOOKUP($C$17,$C$4:$J$13,COLUMNS($C4:I4)),"Name Not Avaible") -> 73 | J17: =IFERROR(VLOOKUP($C$17,$C$4:$J$13,COLUMNS($C4:J4)),"Name Not Avaible") -> 71

Sheet Day-20
C2: Student)_Data2
C3: VLOOKUP- VLOOKUP MULTIPLE CELLS AT ONCE IN EXCEL
C5: Student | D5: Eng | E5: Maths | F5: Science | G5: History | H5: Geography | I5: French
C6: Mike | D6: =VLOOKUP($C6,data2,COLUMNS($C5:D5),0) -> 49 | E6: =VLOOKUP($C6,data2,COLUMNS($C5:E5),0) -> 43 | F6: =VLOOKUP($C6,data2,COLUMNS($C5:F5),0) -> 77 | G6: =VLOOKUP($C6,data2,COLUMNS($C5:G5),0) -> 38 | H6: =VLOOKUP($C6,data2,COLUMNS($C5:H5),0) -> 34 | I6: =VLOOKUP($C6,data2,COLUMNS($C5:I5),0) -> 81

Sheet Data_2
C1: Student)_Data
C3: Student | D3: Eng | E3: Maths | F3: Science | G3: History | H3: Geography | I3: French
C4: Jhon | D4: 51 | E4: 96 | F4: 31 | G4: 97 | H4: 69 | I4: 84
C5: Mike | D5: 49 | E5: 43 | F5: 77 | G5: 38 | H5: 34 | I5: 81
C6: Aman | D6: 56 | E6: 49 | F6: 47 | G6: 93 | H6: 97 | I6: 99
C7: Rajeev | D7: 30 | E7: 54 | F7: 45 | G7: 62 | H7: 80 | I7: 90
C8: Ashish | D8: 35 | E8: 86 | F8: 43 | G8: 54 | H8: 81 | I8: 78
C9: Charlie | D9: 81 | E9: 30 | F9: 45 | G9: 79 | H9: 36 | I9: 99
C10: Quarrat | D10: 62 | E10: 74 | F10: 53 | G10: 92 | H10: 96 | I10: 85
C11: Raju | D11: 71 | E11: 73 | F11: 97 | G11: 93 | H11: 58 | I11: 32
C12: Janice | D12: 91 | E12: 64 | F12: 52 | G12: 51 | H12: 90 | I12: 77
C13: Kalvin | D13: 42 | E13: 30 | F13: 56 | G13: 90 | H13: 66 | I13: 53
C14: Douglas | D14: 96 | E14: 30 | F14: 64 | G14: 74 | H14: 46 | I14: 71
C15: Munni | D15: 75 | E15: 35 | F15: 68 | G15: 62 | H15: 47 | I15: 40
... C17: Shalu | D17: 83 | E17: 95 | F17: 71 | G17: 46 | H17: 58 | I17: 58

Sheet Day-21
A1: IF(ISTEXT(E18),VLOOKUP(E18,C11:D16,2,0),VLOOKUP(E18,B11:D16,3,0))
K2: Diya
B3: Value | C3: Result | K3: Karan
B4: 1 | C4: =ISTEXT(B4) -> FALSE | K4: Charlie
B5: 28756 | C5: =ISTEXT(B5) -> FALSE | E5: =N(B5) -> 28756 | K5: Superman
C6: =ISTEXT(B6) -> FALSE | K6: 1
B7: =1/0 -> #DIV/0! | C7: =ISTEXT(B7) -> FALSE | K7: 2
B8: BYE | C8: =ISTEXT(B8) -> TRUE | K8: 3
K9: 4
K10: 5
B11: Roll Number | C11: Name | D11: Marks
B12: 1 | C12: Neil | D12: 95
B13: 2 | C13: Diya | D13: 92
B14: 3 | C14: Karan | D14: 89
B15: 4 | C15: Charlie | D15: 92
B16: 5 | C16: Superman | D16: 96
B18: Type Student Name or Roll Number : | E18: Karan
B19: The Marks are : | E19: =IF(ISTEXT(E18),VLOOKUP(E18,C11:D16,2,0),VLOOKUP(E18,B11:D16,3,0)) -> 89

Sheet Day-22
A1: IF(ISNUMBER(E18),VLOOKUP(E18,B11:D16,3,0),VLOOKUP(E18,C11:D16,2,0))
B3: Value | C3: Result | L3: Neil
B4: 1 | C4: =ISNUMBER(B4) -> TRUE | L4: Diya
B5: 28756 | C5: =ISNUMBER(B5) -> TRUE | E5: =N(B5) -> 28756 | G5: N(B5) | L5: Karan
C6: =ISNUMBER(B6) -> FALSE | L6: Charlie
B7: =1/0 -> #DIV/0! | C7: =ISNUMBER(B7) -> FALSE | L7: Superman
B8: BYE | C8: =ISNUMBER(B8) -> FALSE | L8: 1
L9: 2
L10: 3
B11: Roll Number | C11: Name | D11: Marks | L11: 4
B12: 1 | C12: Neil | D12: 95 | L12: 5
B13: 2 | C13: Diya | D13: 92
B14: 3 | C14: Karan | D14: 89
B15: 4 | C15: Charlie | D15: 92
B16: 5 | C16: Superman | D16: 96
B18: Type Student Name or Roll Number : | E18: Karan
B19: The Marks are : | E19: =IF(ISNUMBER(E18),VLOOKUP(E18,B11:D16,3,0),VLOOKUP(E18,C11:D16,2,0)) -> 89

Sheet Day-23
B1: VLOOKUP WITH MID FORMULA VERY ADVANCE USERS ONLY
B2: VLOOKUP(MID(B5,6,2)+0,E4:F8,2,0)
B4: ID | C4: Product Name | E4: CODE | F4: PRODUCT NAME | I4: ID | J4: CODE
B5: APPN-45-XYZ | C5: =VLOOKUP(MID(B5,6,2)+0,E4:F8,2,0) -> Iphone | E5: 45 | F5: Iphone | I5: APPN-45-XYZ
B6: QWWR-56-TYV | C6: =VLOOKUP(MID(B6,6,2)+0,E5:F9,2,0) -> Ipad | E6: 56 | F6: Ipad | I6: QWWR-56-TYV
B7: ERRT-89-UHG | C7: =VLOOKUP(MID(B7,6,2)+0,E6:F10,2,0) -> Galaxy Tab | E7: 89 | F7: Galaxy Tab | I7: ERRT-89-UHG
B8: RTTY-98-lHJ | C8: =VLOOKUP(MID(B8,6,2)+0,E7:F11,2,0) -> HTC | E8: 98 | F8: HTC | I8: RTTY-98-lHJ

Sheet Day-24
B1: SUM & SUMPRODUCT | I1: SUM
B2: SUM(G5:G17) & SUMPRODUCT(E5:E17,F5:F17) | I2: SUM(L11*M11)
I3: S.No | J3: Item | K3: Company | L3: Rate | M3: Qty | N3: Total
B4: S.No | C4: Item | D4: Company | E4: Rate | F4: Qty | G4: Total | I4: 1 | J4: CD | K4: Writex | L4: 10 | M4: 50 | N4: =SUM(L4*M4) -> 500
B5: 1 | C5: CD | D5: Writex | E5: 10 | F5: 50 | G5: =E5*F5 -> 500 | I5: 2 | J5: RAM | K5: Kingston | L5: 450 | M5: 15 | N5: =SUM(L5*M5) -> 6750
B6: 2 | C6: RAM | D6: Kingston | E6: 450 | F6: 15 | G6: =E6*F6 -> 6750 | I6: 3 | J6: MONITOR | K6: LG | L6: 4100 | M6: 10 | N6: =SUM(L6*M6) -> 41000
B7: 3 | C7: MONITOR | D7: LG | E7: 4100 | F7: 10 | G7: =E7*F7 -> 41000 | I7: 4 | J7: DVD | K7: Writex | L7: 15 | M7: 40 | N7: =SUM(L7*M7) -> 600
B8: 4 | C8: DVD | D8: Writex | E8: 15 | F8: 40 | G8: =E8*F8 -> 600 | I8: 5 | J8: RAM | K8: Samsung | L8: 550 | M8: 10 | N8: =SUM(L8*M8) -> 5500
B9: 5 | C9: RAM | D9: Samsung | E9: 550 | F9: 10 | G9: =E9*F9 -> 5500 | I9: 6 | J9: CD | K9: Tips | L9: 10 | M9: 45 | N9: =SUM(L9*M9) -> 450
B10: 6 | C10: CD | D10: Tips | E10: 10 | F10: 45 | G10: =E10*F10 -> 450 | I10: 7 | J10: MOUSE | K10: Quantam | L10: 250 | M10: 12 | N10: =SUM(L10*M10) -> 3000
B11: 7 | C11: MOUSE | D11: Quantam | E11: 250 | F11: 12 | G11: =E11*F11 -> 3000 | I11: 8 | J11: DVD | K11: Writex | L11: 15 | M11: 50 | N11: =SUM(L11*M11) -> 750
B12: 8 | C12: DVD | D12: Writex | E12: 15 | F12: 50 | G12: =E12*F12 -> 750
B13: 9 | C13: CD | D13: Writex | E13: 10 | F13: 50 | G13: =E13*F13 -> 500 | I13: SUMSQ
B14: 10 | C14: RAM | D14: Kingston | E14: 500 | F14: 5 | G14: =E14*F14 -> 2500 | I14: SUMSQ(I18,J18,K18,L18)
B15: 11 | C15: MOUSE | D15: Intex | E15: 150 | F15: 12 | G15: =E15*F15 -> 1800 | I15: No. 1 | J15: No. 2
B16: 12 | C16: MONITOR | D16: AOC | E16: 4050 | F16: 6 | G16: =E16*F16 -> 24300 | I16: 5 | J16: 3 | M16: =SUMSQ(I16,J16) -> 34
B17: 13 | C17: CD | D17: Tips | E17: 10 | F17: 55 | G17: =E17*F17 -> 550 | I17: 3 | J17: 4 | K17: 5 | M17: =SUMSQ(I17,J17,K17) -> 50
C18: Total | F18: =SUM(F5:F17) -> 360 | G18: =SUM(G5:G17) -> 88200 | I18: 6 | J18: 3 | K18: 3 | L18: 4 | M18: =SUMSQ(I18,J18,K18,L18) -> 70
G19: =SUMPRODUCT(E5:E17,F5:F17) -> 88200
B21: SUMIF :- SUMIF('Day-24'!C25:C54,J25,'Day-24'!G25:G54) | I21: SUMX2MY2 , SUMX2PY2 & SUMXMY2
B22: SUMIFS :- SUMIFS('Day-24'!G25:G54,'Day-24'!C25:C54,J25,'Day-24'!D25:D54,I25)
B24: S.No | C24: Item | D24: Company | E24: Rate | F24: Qty | G24: Total | I24: (X2-Y2)=(X+Y)*(X-Y) | M24: =SUMX2MY2()
B25: 1 | C25: CD | D25: Writex | E25: 10 | F25: 50 | G25: =E25*F25 -> 500 | I25: No. 1 | J25: No. 2
B26: 2 | C26: RAM | D26: Kingston | E26: 450 | F26: 15 | G26: =E26*F26 -> 6750 | I26: 5 | J26: 3 | K26: =SUMX2MY2(I26,J26) -> 16 | L26: =I26^2-J26^2 -> 16 | M26: =(I26+J26)*(I26-J26) -> 16
B27: 3 | C27: MONITOR | D27: LG | E27: 4100 | F27: 10 | G27: =E27*F27 -> 41000 | I27: 3 | J27: 4
B28: 4 | C28: DVD | D28: Writex | E28: 15 | F28: 40 | G28: =E28*F28 -> 600 | I28: 6 | J28: 3
B29: 5 | C29: RAM | D29: Samsung | E29: 550 | F29: 10 | G29: =E29*F29 -> 5500
B30: 6 | C30: CD | D30: Tips | E30: 10 | F30: 45 | G30: =E30*F30 -> 450 | I30: (X2+Y2)=(X+Y)2-2XY | M30: =SUMX2PY2()
B31: 7 | C31: MOUSE | D31: Quantam | E31: 250 | F31: 12 | G31: =E31*F31 -> 3000
B32: 8 | C32: DVD | D32: Writex | E32: 15 | F32: 50 | G32: =E32*F32 -> 750 | I32: No. 1 | J32: No. 2
B33: 9 | C33: CD | D33: Writex | E33: 10 | F33: 50 | G33: =E33*F33 -> 500 | I33: 9 | J33: 3 | K33: =SUMX2PY2(I33,J33) -> 90
B34: 10 | C34: RAM | D34: Kingston | E34: 500 | F34: 5 | G34: =E34*F34 -> 2500 | I34: 3 | J34: 4
B35: 11 | C35: MOUSE | D35: Intex | E35: 150 | F35: 12 | G35: =E35*F35 -> 1800 | I35: 6 | J35: 3
B36: 12 | C36: MONITOR | D36: AOC | E36: 4050 | F36: 6 | G36: =E36*F36 -> 24300
B37: 13 | C37: CD | D37: Tips | E37: 10 | F37: 55 | G37: =E37*F37 -> 550 | I37: (X-Y)2 =X2+Y2-2XY | M37: =SUMXMY2()
B38: 14 | C38: DVD | D38: Tips | E38: 15 | F38: 35 | G38: =E38*F38 -> 525
B39: 15 | C39: RAM | D39: Samsung | E39: 600 | F39: 10 | G39: =E39*F39 -> 6000 | I39: No. 1 | J39: No. 2
B40: 16 | C40: CD | D40: Writex | E40: 10 | F40: 50 | G40: =E40*F40 -> 500 | I40: 9 | J40: 3 | K40: =SUMXMY2(I40,J40) -> 36
B41: 17 | C41: RAM | D41: Kingston | E41: 450 | F41: 15 | G41: =E41*F41 -> 6750 | I41: 3 | J41: 4
B42: 18 | C42: MONITOR | D42: LG | E42: 4100 | F42: 10 | G42: =E42*F42 -> 41000 | I42: 6 | J42: 3
...

Sheet Day-25
B3: S.No | C3: A | D3: B | E3: C | F3: D
B4: 1 | C4: 33.45 | D4: 56.76 | E4: 32.12 | F4: 76
B5: 2 | C5: 56 | D5: 88.98 | E5: 33 | F5: 77
B6: 3 | C6: 67.78 | D6: 67.77 | E6: 66 | F6: 78.66
B7: 4 | C7: 45 | D7: 45.66 | E7: 77 | F7: 55.67
B8: 5 | C8: 56 | D8: 44 | E8: 45 | F8: 55
B9: 6 | C9: 54.44 | D9: 56 | E9: 67.89 | F9: 55
B10: 7 | C10: 34.45 | D10: 66 | E10: 89 | F10: 45
B11: 8 | C11: 32.56 | D11: 44 | E11: 67 | F11: 55.98
B12: 9 | C12: 56 | D12: 67.67 | E12: 45 | F12: 45
B13: 10 | C13: 78 | D13: 56.67 | E13: 33 | F13: 56
A15: MEAN | C15: =AVERAGE(C4:C13) -> 51.368 | D15: =AVERAGE(D4:D13) -> 59.351 | E15: =AVERAGE(E4:E13) -> 55.501 | F15: =AVERAGE(F4:F13) -> 59.931
A16: MEDIAN | C16: =MEDIAN(C4:C13) -> 55.22 | D16: =MEDIAN(D4:D13) -> 56.715 | E16: =MEDIAN(E4:E13) -> 55.5 | F16: =MEDIAN(F4:F13) -> 55.825
A17: MODE | C17: =MODE(C4:C13) -> 56 | D17: =MODE(D4:D13) -> 44 | E17: =MODE(E4:E13) -> 33 | F17: =MODE(F4:F13) -> 55
A18: STANDEARD DEVIATION | C18: =STDEVA(C4:C13) -> 15.106975 | D18: =STDEVA(D4:D13) -> 13.928597 | E18: =STDEVA(E4:E13) -> 20.439984 | F18: =STDEVA(F4:F13) -> 12.666918

Sheet Day-26
B1: IF FORMMULA
B2: IF(D4>=$D$8,$D$9,$D$10)
B4: Superman's Sales For This Month | C4: 200000 | D4: 99999 | E4: 44000
B5: Superman's Incentive | C5: =IF(C4>=$C$8,$C$9,$C$10) -> 400 | D5: =IF(D4>=$C$8,$C$9,$C$10) -> 65 | E5: =IF(E4>=$C$8,$C$9,$C$10) -> 65
B7: Condition
B8: Superman's Sales Traget | C8: 100000
B9: Incentive if target met | C9: 400
B10: Incentive if target not met | C10: 65
B13: IF FORMMULA (Get Text as Answer)
B14: IF(C16>C17,"Net Profit", "Net Loss")
B16: Total Sales | C16: 9000
B17: Total Cost | C17: 6000
B18: =IF(C16>C17,"Net Profit", "Net Loss") -> Net Profit | C18: =C16-C17 -> 3000
B21: IF FORMMULA (Used as Condition)
B22: IF(C24>C25,C24-C25,C25-C24)
B24: Total Sales | C24: 4500
B25: Total Cost | C25: 5000
B26: =IF(C24>C25,"Net Profit", "Net Loss") -> Net Loss | C26: =IF(C24>C25,C24-C25,C25-C24) -> 500
B29: If Formula - (Put a formula in the If Condition)
B32: Superman's Sales For This Month | C32: 110000
B33: Superman's Incentive | C33: =IF(C32>=C36,C32*C37,"Zero") -> 11000
A35: 0.01 | B35: Condition
B36: Superman's Sales Target | C36: 100000
B37: Incentive % | C37: 0.1

Sheet SAMPLE
